# 问题描述

在项目转化过程中我遇到了一个与 CAS (Compare and Swap) [2] 操作实现相关的问题，在计算机科学中CAS 是多线程/协程中用于实现同步的原子指令。该软件针对不同的芯片平台，通过在C语言中根据芯片平台的类别进行宏定义并嵌入相应的汇编代码来实现CAS操作。我知道不同芯片平台对应的 CAS 操作的汇编代码是不一样的 [3]，例如：

x86-64 (Intel/AMD) 需要类似如下汇编代码块：

    lock cmpxchgq [destination], rdx
ARM 需要类似如下汇编代码块：

    ldrex r1, [destination]
    cmp r1, r2
    strexeq r1, r2, [destination]
PowerPC 需要类似如下汇编代码块：

    lwarx r0, 0, destination
    cmpw r0, r1
    bne retry ; branch if not equal
    stwcx. r2, 0, destination
    bne retry ; branch if store failed
然而如下面的代码片段所示，即使该软件使用相同的Intel x86芯片平台，但是在不同的操作系统平台上其实现的汇编指令也有可能是不一样的。

C头文件中 cas_operation.h 的部分代码如下：
#if defined(__i386) || defined(__x86_64__) || defined(__sparcv9) || defined(__sparcv8plus)
typedef unsigned int slock_t;
#else
typedef unsigned char slock_t;
#endif
extern slock_t my_atomic_cas(volatile slock_t *lock, slock_t with, slock_t cmp);
#define TAS(a) (my_atomic_cas((a), 1, 0) != 0)
#endif
对应实现的x86汇编文件 cas_operation.s 的部分代码如下：
my_atomic_cas:
#if defined(__amd64)
 movl       %edx, %eax
 lock
 cmpxchgl   %esi, (%rdi)
#else
 movl    4(%esp), %edx
 movl    8(%esp), %ecx
 movl    12(%esp), %eax
 lock
 cmpxchgl %ecx, (%edx)
#endif
 Ret
众所周知虽然Rust也有宏定义的包 Macros，但是目前也与C语言的有不小的差别。因此，在做转化的过程中如何做到芯片平台和操作系统级别的代码兼容则是我遇到的最大挑战。

## 解决方案

想到两个解决方案：

使用asm! 宏去处理不同芯片平台的汇编代码
使用 Rust代码对特定的操作进行针对性的实现
第一种方案比较简单，只需要在代码中使用std::arch::asm 包，然后使用 asm! 宏（类似 println! 宏）去包裹不同平台的汇编代码即可，这也是最直接最容易想到的解决方案，而且无需考虑具体的汇编操作实现的指令和代码。但是这方法杂糅了很多的不同平台的汇编代码，同时需要Rust做很多额外的平台相关的逻辑控制，对这些控制逻辑部分代码的维护也是一个持久且复杂的工作。比如对新的平台指令 RSIC-V 的支持也要纳入其中。

第二种方案则需要考虑具体的操作逻辑，然后通过Rust代码去实现与汇编指令相同的逻辑，虽然有较大的工作量，但是这种方案可以消除由于芯片和系统平台不同带来的各种汇编代码实现的差异。 关于第一种方案的实现读者可以参照文档 Inline assembly [4] 中去做。针对 CAS 操作的第二种方案的实现则是本文主要提出的一种解决方案，而本文以类似Rust u32类型的 CAS 操作为例子实现其代码，在 my_compare_and_swap.rs 中会有如下代码段实现：

use std::sync::atomic::{AtomicU32, Ordering};

pub type uint32 = libc::c_uint;
pub struct my_atomic_uint32 {
 pub value: uint32,
}

impl my_atomic_uint32 {
    #[inline]
    pub fn compare_and_swap(&self, expected: uint32, newval: uint32) -> bool {
        let atomic_ptr = self as *const my_atomic_uint32 as *const AtomicU32;
        let atomic = unsafe { &*(atomic_ptr) };
        atomic.compare_and_swap(expected, newval, Ordering::SeqCst) == expected
    }
}

pub fn my_compare_and_swap_u32_impl(
    mut ptr: *mut pg_atomic_uint32,
    mut expected: *mut uint32,
    mut newval: uint32,
) -> bool {
 let atomic = &*ptr;
 atomic.compare_and_swap(*expected, newval)
}

下面我来解释一下上面的代码。由于是从 C 转到 Rust，因此我使用了 Rust 的 libc 包来自定义 uint32类型。然后通过自定义struct my_atomic_uint32 来对uint32进行CAS原子操作的包裹，同时对于此 struct实现其 inline 的compare_and_swap 操作函数。在该函数的实现中最关键的是将my_atomic_uint32的实体转化为一个AtomicU32的常量（注意需要在 Rust 代码文件开头使用 std::sync::atomic::{AtomicU32, Ordering} [5]），然后通过调用 AtomicU32 的compare_and_swap 来最终实现 uint32 的 CAS 操作。另外对于Ordering::SeqCst内存顺序 [6] 的选择也是比较考究的一个话题，这里我使用 SeqCst实际上是一个在保证正确的情况下不太考虑效率优化问题的选项。代码的最后my_compare_and_swap_u32_impl 则是对外使用的 u32 的 CAS 操作（事实上该软件主要也是需要实现 uint32 的 CAS 操作）。

## 结论

在本例中由于刚好有对应AtomicU32的CAS 实现，而且软件中整个原子同步的代码部分都是使用uint32进行的比较交换操作，因此我选择第二种方案则是最佳选择。由此可知上述的两种解决方案其实是各有利弊的，我必须结合实际的应用场景才能去做决定。那么这里有一个问题，如果需要对许多数据类型(比如uint32, int32, uint64, int64, float, float32, float64……)进行比较交换操作，又该做何种选择呢？这也许是仁者见仁智者见智的。

## 系统环境问题

本文将记录转化过程中遇到的另外一个问题。该问题是由已经转化完成的 Rust 代码使用到软件中引入的第三方软件包和链接库所导致的。设想这样一个场景：Rust 项目中完成某一个功能点需要用到一个或多个第三方软件包和链接库。这显然是很常见的用户场景，但是由于用户环境不同，用户安装的第三方软件包和链接库的版本不同，使得转化后的 Rust 代码必须要做适当的兼容处理。

这里所说的用户的环境不同，可以理解为芯片指令集的平台不同，如 Intel x86 以及国产的 ARM 麒麟服务器。当然更常见的情形是芯片平台相同，但是存在操作系统层面第三方软件包和链接库安装的差异，如 x86 下的 Ubuntu 和 CentOS 中用户安装了不同版本的第三方软件包和链接库等。

事实上，即使排除所有平台和系统层面的差异，由于用户安装了该基础软件所依赖的不同版本的第三方软件包和链接库，然而这些第三方软件包或者链接库由于自身的演进导致不同版本之间存在较大差异（可能实现相同功能的函数和函数签名都有千差万别），这给我重写该软件的工作带来了一些挑战。基于上述说明，在完成重写该基础软件的过程中如何使得转化后的 Rust 代码能兼容该基础软件所依赖的主流第三方软件包和链接库则是我遇到的最大挑战。需要说明的是这里的第三方软件包和链接库可能是基于 Rust 语言开发的，也可能是基于 C 语言开发的。

### 解决方案

对于此问题的解决方案需要使用 Rust FFI(Foreign Function Interface) [1]，这基本上是没有太大争议的。因为在本次软件重写过程中我遇到的场景是：对于不同版本的链接库使用哪个版本的函数取决于用户的安装运行时环境，所以除了 Rust FFI，在代码适配上我还考虑了使用 Rust features [2] 机制。

下面我简化了一下场景和解决方案，同时我把样本代码放到了我的 github [3] 里，欢迎大家一起交流。如样本代码所示，my-rust-bin 文件夹中的一段业务代码需要调用到静态链接库 my_rust_lib 中的函数，该链接库有两个版本 v1（在文件夹 my-rust-lib-v1 中） 和 v2（在文件夹 my-rust-lib-v2 中）， 且不同版本的库其函数不一样。

my-rust-lib-v1 对应的业务函数为：pub fn my_rust_lib_v1(left: usize, right: usize) -> usize
my-rust-lib-v2 对应的业务函数为：pub fn my_rust_lib_v2(left: usize, right: usize) -> usize
另外一个 lib 文件夹的目的其实是为了模拟用户本地安装的链接库。可以分别编译不同版本的静态链接库，然后把生成的库文件（在本例中是）libmy_rust_lib.a, 然后把不同版本的库文件拷贝到此文件夹下，以此来模拟用户环境中安装的不同版本的链接库。解决方案中的关键点在于 my-rust-bin 中，

首先在 my-rust-bin 的 Cargo.toml 中有定义对应的 features，如下所示：

```toml
[features]
v1 = []
v2 = []
```

其次在 my-rust-bin 的 src/main.rs 下的代码如下：

```rust
#[cfg(feature = "v1")]
mod bindingmylib {
    extern "C" {
        pub fn my_rust_lib_v1(left: usize, right: usize) -> usize;
    }
}

#[cfg(feature = "v2")]
mod bindingmylib {
    extern "C" {
        pub fn my_rust_lib_v2(left: usize, right: usize) -> usize;
    }
}

#[cfg(not(any(feature = "v1", feature = "v2")))]
compile_error!("Please specify either 'v1' or 'v2' feature");

pub fn my_rust_lib(left: usize, right: usize) -> usize {
    #[cfg(feature = "v1")]
    unsafe {
        return bindingmylib::my_rust_lib_v1(left, right);
    }

    #[cfg(feature = "v2")]
    unsafe {
        return bindingmylib::my_rust_lib_v2(left, right);
    }
}

fn main() {
    let r_value: usize = my_rust_lib(3, 5);
    println!("The return value of my_rust_lib is [{}]", r_value);
}
```
现在我来解读一下这段代码。代码先分别定义一个相同的模块 bindingmylib，然后根据 features 分别引入的依赖，使用的不同的静态链接库函数（my_rust_lib_v1 和 my_rust_lib_v2）, 同时通过 compile_error! 定义一个没有设置 v1 和 v2 features 的编译错误（防止编译时忘记设置 features选项，下面在编译环节的时候有用）。最后将两个有差异的函数统一为函数 my_rust_lib，并在该函数中根据 features 定义分别调用不同的函数并返回相应的值。

最后是在 my-rust-bin 中编译二进制文件：

```shell
# 编译 v1 版本的 my-rust-bin
$ cd my-rust-bin
$ cargo build --features="v1"

# 运行 v1 版本的 my-rust-bin
$ target/debug/my-rust-bin
my_rust_lib_v1: 8
The return value of my_rust_lib is [8]
```

编译并运行 v2 的二进制文件:
```sh
# 编译 v2 版本的 my-rust-bin
$ cd my-rust-bin
$ cargo build --features="v2"

# 运行 v2 版本的 my-rust-bin
$ target/debug/my-rust-bin
my_rust_lib_v2: 8
The return value of my_rust_lib is [8]
```

备注：如果编译的时候没有设置 --features 则会有如下输出：
```sh
$ cargo build
error: Please specify either 'v1' or 'v2' feature
  --> src/main.rs:16:1
   |
16 | compile_error!("Please specify either 'v1' or 'v2' feature");
   | ^^^^^^^^^^^^^^^^^^^^^^^^^^^^^^^^^^^^^^^^^^^^^^^^^^^^^^^^^^^^
```
至此，用户在编译好该基础软件之后，就可以无感知的通过统一的函数入口调用不同版本的相同链接库中的不同函数了。

### 总结
本文主要是在简化了问题的实际场景以后，解决不同版本的同一软件包或者链接库中，函数及其函数签名不同导致的调用问题。之所以说简化，主要是本文所描述的场景中，my-rust-bin 和其依赖的外部链接库均是 Rust 编写。而在我的实际场景中则会更复杂一些，存在着 Rust 代码依赖 C 编写的外部链接库，同时存在混合的原来 C 代码部分依赖新改写的 Rust 外部链接库的情况。但是无论哪种情况，万变不离其宗，我们都可以从这种最简单的场景出发去解决遇到的问题。


## 问题描述

本篇博客继续此次重写实践过程中遇到的新问题：panic 错误处理的问题。大家都知道 Rust 的错误处理机制 [2] 本质上可以分为 Unrecoverable Errors 和 Recoverable Errors。对于前者，当非常糟糕的情况出现时用户可以选择通过 panic! 宏来创建不可恢复的错误（当然也有可能是由于代码运行时出现的隐式错误，例如除零，数组越界等）。对于后者，一般会通过 Rust 的 Result（其本质是一个特别的枚举类型，只含有 OK 和 Err 两个枚举成员）来处理可能出现的错误，如文件打开错误，文件读写错误等。关于 除零 的 panic 错误有一点需要解释一下。得益于 Rust 强大的编译器，与其他编程语言如 C 和 Golang 不太一样，如下的 Rust 代码其实在编译阶段就会报错：

fn main() {
    let numerator = 42;
    let denominator = 0;

    // This line will result in a compilation error
    let result = numerator / denominator;

    println!("Result: {}", result);
}
对于上面的代码编译器会报错如下（我环境中的 Rust 版本为：rustc 1.75.0 (82e1608df 2023-12-21)）：

error: this operation will panic at runtime
 --> src/main.rs:6:18
  |
6 |     let result = numerator / denominator;
  |                  ^^^^^^^^^^^^^^^^^^^^^^^ attempt to divide `42_i32` by zero
  |
  = note: `#[deny(unconditional_panic)]` on by default
额外说明一下：我指出这个问题并不是说 除零 的错误不会在 Rust 中发生，而是想说明 Rust 语言本身是尽可能在编译阶段就帮助工程师找出代码错误，使其代码更健壮可靠。

言归正传，我遇到的问题就是需要处理 Rust 代码中出现的运行时 Unrecoverable Errors，不能让程序由于这种不可恢复的错误停下来。有读者可能会问：既然 Rust 定义了 Unrecoverable Errors, 那就是不可恢复的错误，我为什么还固执的需要处理这种错误呢？回答这个问题还是需要结合我的场景来讨论。首先既然我的场景是把 C 语言编写的一个基础软件转化为 Rust （暂时还不能实现 100% 的转化），因此就会有些情况与完全用 Rust 编写的项目不太一样。并且我认为一个项目中既有 C 代码又有 Rust 代码的情形在未来很长的时间里将会是一个常态（比如目前 Linux 已经有 Rust 实现的 patch，未来相信还会有其他的 Rust patch）。关于上面提到的 “不一样” 的情形，在此我可以举一个例子。大家知道，在 C 语言中将一个数组作为参数传递给一个函数有如下三种方式 [3] ：

将数组作为指针变量传递给函数
void foo(int* array)
将数组作为一个引用传递给函数
void foo(int array[])
将数组以一个指定 size 大小的数组传递给函数
void foo(int array[SIZE])
在 C 语言中有多种方式把一个数组传递给函数，不仅如此，大家知道在 C 语言中出现数组越界访问时，其行为是不可预测的，即有可能出错，也有可能不出错。那么针对这种情形，当我们需要把浩瀚的 C 代码转化为 Rust 代码的时候，原来 C 代码可能不会报错，但是 Rust 代码中却会出现数组访问越界的 panic 错误，当然这只是一个个例。在 Rust 中，大家习惯性的使用 unwrap() 去处理可能出现的 panic 错误，在纯 Rust 的项目中也许大家有足够的信心进退自如，去决定该怎样处理这样的问题。但是在混合状态下，比如 C 和 Rust 相互混合的项目中，在某些情况下由于类似的问题会导致整个程序终止，这些行为也许并不是我们预期的。因此在处理混合项目中出现隐式 panic 错误时，使其在隐式的 panic 错误发生后依然能够被正确处理而不会使整个程序终止，则是我在此次实践中需要解决的问题。

### 解决方案

在解决这个问题时，我首先考虑到的是在 Rust 中寻找类似 Golang 的 panic 恢复机制 [4]。遗憾的是，虽然 Rust 提供了 panic hook [5] 的机制，允许用户在 panic 错误发生时自定义一些行为，但是 panic hook 并不能解决程序终止的问题，所以目前看来，Rust 中并没有类似的 panic 恢复机制，并且不十分坚定的认为：不可恢复的错误就不应该恢复。我之所以说是“不十分坚定”是因为 Rust 在 std::panic::catch_unwind [6] 中给我解决这个问题留下了一定的空间。std::panic::catch_unwind 主要是通过调用一个闭包来捕获在其中可能发生的 panic 错误。而我也基于这个办法，在做了相应的试验后，将其运用到了转化的项目中，同时我把试验的样本代码放到了我的 github [7] 里，欢迎大家一起交流。在样本代码中，主要有两个文件夹分别对应两种情况：

rust-panic-without-handling 是没有处理 panic 错误的二进制程序代码文件夹。
rust-panic-with-handling 是通过 std::panic::catch_unwind 处理了许多 panic 错误的二进制程序代码文件夹。这些 panic 错误包括：divided by zero，InvalidDigit 和 out of index range panic。
上面两个 Rust 程序试验的逻辑主要是用户通过标准 IO 输入做 3 次循环输入，每次输入计算所需的 分子 和 分母，然后通过 Rust 代码做 分子/分母 的操作计算，再之后将计算结果存储到固定长度为 3 的 i32 数组中，最后遍历该数组，并输出数组中的值。试验场景如下：

可以在任意的输入循环中，将 分母 输入为 0 引发 divided by zero panic 错误
可以在任意的输入循环中输入非数字的值，如输入 56x 引发 InvalidDigit panic 错误
也是肯定要发生的错误。通过访问从 0 到 3 的元素索引固定长度为 3 的数组来引发 out of index range panic 错误
对于不处理 panic 错误的样本代码如下：

use std::io;
use std::io::Write;

fn main() {
    let mut try_times: i32 = 0;
    let mut int_array: [i32; 3] = [0; 3];
    println!("\n ###### Divide by zero ###### \n");
    while try_times < 3 {
        let current_time = try_times as usize;
        
        // Get numerator from user input
        let mut numerator = String::new();
        print!("Please input the numerator: ");
        io::stdout().flush().unwrap();
        io::stdin().read_line(&mut numerator).expect("Failed to read line");
        let numerator: i32 = numerator.trim().parse().expect("Invalid input");
        
        // Get denominator from user input
        let mut denominator = String::new();
        print!("Please input the denominator: ");
        io::stdout().flush().unwrap();
        io::stdin().read_line(&mut denominator).expect("Failed to read line");
        let denominator: i32 = denominator.trim().parse().expect("Invalid input");
        
        // Perform division without validation
        int_array[current_time] = numerator / denominator;
        println!("Result is: {:?}", int_array[current_time]);
        try_times += 1;
        println!("##########################################");
    }

    println!("\n @@@@@@ Iteration @@@@@@ \n");
    for i in 0..=3 {
        println!("Iterate Element: {}", int_array[i]);
        println!("@@@@@@@@@@@@@@@@@@@@@@@@@@@@@@@@@@@@@@@@@@");
    }
    
    println!("Complete the panic handle examples!");
}
由上面的 Rust 代码可知，无论任何 panic 错误被触发，整个程序立即终止，而且对于最后一行代码 println!("Complete the panic handle examples!"); 的输出是永远也看不到的。

对于通过 std::panic::catch_unwind 处理 panic 错误的样本代码如下：

use std::io;
use std::io::Write;
use std::panic;

fn main() {
    let mut try_times: i32 = 0;
    let mut int_array: [i32; 3] = [0; 3];
    println!("\n ###### Divide by zero ###### \n");
    while try_times < 3 {
        let current_time = try_times as usize;

        // Handle divide by zero panic
        let result_value = panic::catch_unwind(|| {
            println!("This is the {}th to handle panic.", current_time);
            // Get numerator from user input
            let mut numerator = String::new();
            print!("Please input the numerator: ");
            io::stdout().flush().unwrap();
            io::stdin().read_line(&mut numerator).expect("Failed to read line");
            let numerator: i32 = numerator.trim().parse().expect("Invalid input");
        
            // Get denominator from user input
            let mut denominator = String::new();
            print!("Please input the denominator: ");
            io::stdout().flush().unwrap();
            io::stdin().read_line(&mut denominator).expect("Failed to read line");
            let denominator: i32 = denominator.trim().parse().expect("Invalid input");
        
            // Perform division without validation
            numerator / denominator
        });

        match result_value {
            Ok(result) => {
                println!("No panic occur and the result is: {:?}", result);
                int_array[current_time] = result;
            },
            Err(e) => {
                if let Some(err) = e.downcast_ref::<&str>() {
                    println!("Caught panic: {}", err);
                } else {
                    println!("Caught panic of unknown type");
                }
            },
        };

        try_times += 1;
        println!("##########################################");
    }

    println!("\n @@@@@@ Iteration @@@@@@ \n");

    for i in 0..=3 {
        // Handle out of index range panic
        let num_result = panic::catch_unwind(|| {
            println!("Iterate Element: {}", int_array[i]);
        });

        match num_result {
            Ok(()) => {
                println!("No panic occur for this iteration");
            },
            Err(e) => {
                if let Some(err) = e.downcast_ref::<&str>() {
                    println!("Caught panic: {}", err);
                } else {
                    println!("Caught panic of unknown type");
                }
            },
        };
        println!("@@@@@@@@@@@@@@@@@@@@@@@@@@@@@@@@@@@@@@@@@@");
    }
    
    println!("Complete the panic handle examples!");
}
由上面的 Rust 代码可知，无论任何一个或多个 panic 错误被触发，整个程序始终会一直执行，直到 println!("Complete the panic handle examples!"); 的输出。

对于处理了 panic 错误的代码，我需要做出一些说明和解释。首先 std::panic::catch_unwind 是一个闭包调用，所以对于变量的处理需要谨慎一些。如上所示，在闭包调用中，需要使用到 current_time 来处理数组对应索引元素的更新，该变量不能是可变的 （不能定义为 mut ），所以我做了 let current_time = try_times as usize; 的处理。为什么该闭包中必须是不可变的变量，原因与该闭包传入的数据类型可能实现的 UnwindSafe trait 相关，读者可以去了解需要实现该 trait 的数据类型，本例中是 &i32。读者亦可以删除我处理的相关代码以后看一下报错信息。其次，如果该闭包调用需要返回信息给外部使用，那么可以将返回信息放入调用的返回值中，如上代码所示第一个闭包调用返回的 result_value 会被紧接的 match 代码所使用。最后是一个建议，当使用该闭包的时候请包含尽量少的逻辑代码来实现 panic 错误的捕获，这样可以控制传入的数据类型（受闭包调用的数据类型的限制），同时也能使得 panic 错误的捕获更加精准。当然，std::panic::catch_unwind 是有许多限制的。如文档中所说：它并不能捕获所有的 panic 错误，该函数只捕获展开式 panic，而不捕获终止进程的情况。如果用户已设置了自定义 panic hook，它将在捕获 panic 错误之前被调用，即在展开之前，所以这时候使用 catch_unwind 去捕获 panic 错误可能没有用。另外，使用外部异常（例如从 C++ 代码抛出的异常）展开进入 Rust 代码是未定义行为。
### 总结

本文主要是实现了项目场景中在遇到某些 panic 错误后，对错误进行程序恢复，使得运行程序不会被动终止的方案。在经过调研后发现，Rust 并没有提供整体的 panic 错误恢复机制，但是在综合考虑项目需求和 Rust 提供 std::panic::catch_unwind 后，测验并解决了恢复程序运行的基本功能 且基本满足当前的实践需求。但是需要指出的是，std::panic::catch_unwind 是有一些限制的，并不能完全捕获所有的 panic 错误，因此希望读者在各自项目使用过程中对该方案仍然需要保持谨慎态度。

